<sdf version='1.5'>
  <model name='arm_and_hand'>
    <link name='forearm'>
      <pose>0 0 1.3 1.5707 -5.55112e-17 -1.5707</pose>
      <inertial>
        <pose>0 0 0.09 0 -0 0</pose>
        <mass>3</mass>
        <inertia>
          <ixx>0.001</ixx>
          <ixy>0</ixy>
          <ixz>0</ixz>
          <iyy>0.001</iyy>
          <iyz>0</iyz>
          <izz>0.001</izz>
        </inertia>
      </inertial>
      <collision name='forearm_collision'>
        <pose>0 0 0.09 0 -0 0</pose>
        <geometry>
          <cylinder>
            <length>0.18</length>
            <radius>0.06</radius>
          </cylinder>
        </geometry>
        <surface>
          <contact>
            <ode>
              <kp>100000</kp>
              <kd>100</kd>
              <max_vel>0.1</max_vel>
              <min_depth>0.0015</min_depth>
            </ode>
          </contact>
          <friction>
            <ode>
              <mu>1</mu>
              <mu2>1</mu2>
            </ode>
          </friction>
        </surface>
      </collision>
      <visual name='forearm_visual'>
        <pose>0 0 0 0 -0 0</pose>
        <geometry>
          <mesh>
            <scale>0.001 0.001 0.001</scale>
            <uri>model://sr_description/hand/model/forearm.dae</uri>
          </mesh>
        </geometry>
        <material>
          <script>
            <name>LightGrey</name>
            <uri>__default__</uri>
          </script>
        </material>
      </visual>
      <gravity>1</gravity>
      <velocity_decay>
        <linear>0</linear>
        <angular>0</angular>
      </velocity_decay>
      <self_collide>0</self_collide>
    </link>
    <joint name='arm_base_joint' type='revolute'>
      <child>forearm</child>
      <parent>world</parent>
      <axis>
        <xyz>-1 -9.63268e-05 9.63268e-05</xyz>
        <limit>
          <lower>0</lower>
          <upper>0</upper>
          <effort>10000</effort>
          <velocity>-1</velocity>
        </limit>
        <dynamics>
          <damping>1</damping>
          <friction>0</friction>
          <spring_reference>0</spring_reference>
          <spring_stiffness>0</spring_stiffness>
        </dynamics>
        <use_parent_model_frame>1</use_parent_model_frame>
      </axis>
      <physics>
        <provide_feedback>1</provide_feedback>
        <ode>
          <provide_feedback>1</provide_feedback>
          <implicit_spring_damper>1</implicit_spring_damper>
          <cfm_damping>1</cfm_damping>
          <limit>
            <cfm>0.01</cfm>
            <erp>0</erp>
          </limit>
        </ode>
      </physics>
    </joint>
    <link name='wrist'>
      <pose>-0.213001 -2.05177e-05 1.29002 1.5707 -5.55112e-17 -1.5707</pose>
      <inertial>
        <pose>0 0 0 0 -0 0</pose>
        <mass>0.1</mass>
        <inertia>
          <ixx>0.00012</ixx>
          <ixy>0</ixy>
          <ixz>0</ixz>
          <iyy>0.000148</iyy>
          <iyz>0</iyz>
          <izz>4.38e-05</izz>
        </inertia>
      </inertial>
      <collision name='wrist_collision'>
        <pose>0 0 0 1.5707 -0 0</pose>
        <geometry>
          <cylinder>
            <length>0.03</length>
            <radius>0.015</radius>
          </cylinder>
        </geometry>
        <surface>
          <contact>
            <ode>
              <kp>100000</kp>
              <kd>100</kd>
              <max_vel>0.1</max_vel>
              <min_depth>0.0015</min_depth>
            </ode>
          </contact>
          <friction>
            <ode>
              <mu>1</mu>
              <mu2>1</mu2>
            </ode>
          </friction>
        </surface>
      </collision>
      <visual name='wrist_visual'>
        <pose>0 0 0 0 -0 0</pose>
        <geometry>
          <mesh>
            <scale>0.001 0.001 0.001</scale>
            <uri>model://sr_description/hand/model/wrist.dae</uri>
          </mesh>
        </geometry>
        <material>
          <script>
            <name>PR2/Grey2</name>
            <uri>__default__</uri>
          </script>
        </material>
      </visual>
      <gravity>1</gravity>
      <velocity_decay>
        <linear>0</linear>
        <angular>0</angular>
      </velocity_decay>
      <self_collide>0</self_collide>
    </link>
    <joint name='WRJ2' type='revolute'>
      <child>wrist</child>
      <parent>forearm</parent>
      <axis>
        <xyz>9.63268e-05 9.27885e-09 1</xyz>
        <limit>
          <lower>-0.523599</lower>
          <upper>0.174533</upper>
          <effort>1000</effort>
          <velocity>10</velocity>
        </limit>
        <dynamics>
          <damping>1</damping>
          <friction>0</friction>
          <spring_reference>0</spring_reference>
          <spring_stiffness>0</spring_stiffness>
        </dynamics>
        <use_parent_model_frame>1</use_parent_model_frame>
      </axis>
      <physics>
        <provide_feedback>1</provide_feedback>
        <ode>
          <provide_feedback>1</provide_feedback>
          <implicit_spring_damper>1</implicit_spring_damper>
          <cfm_damping>1</cfm_damping>
          <limit>
            <cfm>0</cfm>
            <erp>0.2</erp>
          </limit>
        </ode>
      </physics>
    </joint>
    <link name='palm'>
      <pose>-0.247001 -2.37928e-05 1.29002 1.5707 -5.55112e-17 -1.5707</pose>
      <inertial>
        <pose>0 0 0.035 0 -0 0</pose>
        <mass>0.3</mass>
        <inertia>
          <ixx>0.0001325</ixx>
          <ixy>0</ixy>
          <ixz>0</ixz>
          <iyy>0.000185</iyy>
          <iyz>0</iyz>
          <izz>7.25e-05</izz>
        </inertia>
      </inertial>
      <collision name='palm_collision'>
        <pose>0 0 0.045 0 -0 0</pose>
        <geometry>
          <box>
            <size>0.08 0.02 0.1</size>
          </box>
        </geometry>
        <surface>
          <contact>
            <ode>
              <kp>100000</kp>
              <kd>100</kd>
              <max_vel>0.1</max_vel>
              <min_depth>0.0015</min_depth>
            </ode>
          </contact>
          <friction>
            <ode>
              <mu>1</mu>
              <mu2>1</mu2>
            </ode>
          </friction>
        </surface>
      </collision>
      <visual name='palm_visual'>
        <pose>0 0 0 0 -0 0</pose>
        <geometry>
          <mesh>
            <scale>0.001 0.001 0.001</scale>
            <uri>model://sr_description/hand/model/palm.dae</uri>
          </mesh>
        </geometry>
        <material>
          <script>
            <name>LightGrey</name>
            <uri>__default__</uri>
          </script>
        </material>
      </visual>
      <gravity>1</gravity>
      <velocity_decay>
        <linear>0</linear>
        <angular>0</angular>
      </velocity_decay>
      <self_collide>0</self_collide>
      <sensor name='palm_contact' type='contact'>
        <always_on>1</always_on>
        <update_rate>1000</update_rate>
        <contact>
          <collision>palm_collision</collision>
          <topic>palm_collision</topic>
        </contact>
      </sensor>
    </link>
    <joint name='WRJ1' type='revolute'>
      <child>palm</child>
      <parent>wrist</parent>
      <axis>
        <xyz>9.63268e-05 -1 5.55112e-17</xyz>
        <limit>
          <lower>-0.7854</lower>
          <upper>0.5236</upper>
          <effort>1000</effort>
          <velocity>10</velocity>
        </limit>
        <dynamics>
          <damping>1</damping>
          <friction>0</friction>
          <spring_reference>0</spring_reference>
          <spring_stiffness>0</spring_stiffness>
        </dynamics>
        <use_parent_model_frame>1</use_parent_model_frame>
      </axis>
      <physics>
        <provide_feedback>1</provide_feedback>
        <ode>
          <provide_feedback>1</provide_feedback>
          <implicit_spring_damper>1</implicit_spring_damper>
          <cfm_damping>1</cfm_damping>
          <limit>
            <cfm>0</cfm>
            <erp>0.2</erp>
          </limit>
        </ode>
      </physics>
    </joint>
    <link name='ffknuckle'>
      <pose>-0.341998 -0.0330329 1.29003 1.5707 -5.55112e-17 -1.5707</pose>
      <inertial>
        <pose>0 0 0 0 -0 0</pose>
        <mass>0.008</mass>
        <inertia>
          <ixx>2e-07</ixx>
          <ixy>0</ixy>
          <ixz>0</ixz>
          <iyy>2e-07</iyy>
          <iyz>0</iyz>
          <izz>2e-07</izz>
        </inertia>
      </inertial>
      <collision name='ffknuckle_collision'>
        <pose>0 0 0 0 1.5707 0</pose>
        <geometry>
          <cylinder>
            <length>0.01</length>
            <radius>0.01</radius>
          </cylinder>
        </geometry>
        <surface>
          <contact>
            <ode>
              <kp>100000</kp>
              <kd>100</kd>
              <max_vel>0.1</max_vel>
              <min_depth>0.0015</min_depth>
            </ode>
          </contact>
          <friction>
            <ode>
              <mu>1</mu>
              <mu2>1</mu2>
            </ode>
          </friction>
        </surface>
      </collision>
      <visual name='ffknuckle_visual'>
        <pose>0 0 0.0005 0 -0 0</pose>
        <geometry>
          <mesh>
            <scale>0.001 0.001 0.001</scale>
            <uri>model://sr_description/hand/model/knuckle.dae</uri>
          </mesh>
        </geometry>
        <material>
          <script>
            <name>Gazebo/Grey</name>
            <uri>__default__</uri>
          </script>
        </material>
      </visual>
      <gravity>1</gravity>
      <velocity_decay>
        <linear>0</linear>
        <angular>0</angular>
      </velocity_decay>
      <self_collide>0</self_collide>
      <sensor name='ffknuckle_contact' type='contact'>
        <always_on>1</always_on>
        <update_rate>1000</update_rate>
        <contact>
          <collision>ffknuckle_collision</collision>
          <topic>ffknuckle_collision</topic>
        </contact>
      </sensor>
    </link>
    <joint name='FFJ4' type='revolute'>
      <child>ffknuckle</child>
      <parent>palm</parent>
      <axis>
        <xyz>-9.63268e-05 -9.27885e-09 -1</xyz>
        <limit>
          <lower>-0.3491</lower>
          <upper>0.3491</upper>
          <effort>1000</effort>
          <velocity>10</velocity>
        </limit>
        <dynamics>
          <damping>1</damping>
          <friction>0</friction>
          <spring_reference>0</spring_reference>
          <spring_stiffness>0</spring_stiffness>
        </dynamics>
        <use_parent_model_frame>1</use_parent_model_frame>
      </axis>
      <physics>
        <provide_feedback>1</provide_feedback>
        <ode>
          <provide_feedback>1</provide_feedback>
          <implicit_spring_damper>1</implicit_spring_damper>
          <cfm_damping>1</cfm_damping>
          <limit>
            <cfm>0</cfm>
            <erp>0.2</erp>
          </limit>
        </ode>
      </physics>
    </joint>
    <link name='ffproximal'>
      <pose>-0.341998 -0.0330329 1.29003 1.5707 -5.55112e-17 -1.5707</pose>
      <inertial>
        <pose>0 0 0.0225 0 -0 0</pose>
        <mass>0.014</mass>
        <inertia>
          <ixx>1e-06</ixx>
          <ixy>0</ixy>
          <ixz>0</ixz>
          <iyy>1e-06</iyy>
          <iyz>0</iyz>
          <izz>5e-07</izz>
        </inertia>
      </inertial>
      <collision name='ffproximal_collision'>
        <pose>0 0 0.025 0 -0 1.5707</pose>
        <geometry>
          <cylinder>
            <length>0.04</length>
            <radius>0.01</radius>
          </cylinder>
        </geometry>
        <surface>
          <contact>
            <ode>
              <kp>100000</kp>
              <kd>100</kd>
              <max_vel>0.1</max_vel>
              <min_depth>0.0015</min_depth>
            </ode>
          </contact>
          <friction>
            <ode>
              <mu>1</mu>
              <mu2>1</mu2>
            </ode>
          </friction>
        </surface>
      </collision>
      <visual name='ffproximal_visual'>
        <pose>0 0 0 0 -0 0</pose>
        <geometry>
          <mesh>
            <scale>0.001 0.001 0.001</scale>
            <uri>model://sr_description/hand/model/F3.dae</uri>
          </mesh>
        </geometry>
        <material>
          <script>
            <name>LightGrey</name>
            <uri>__default__</uri>
          </script>
        </material>
      </visual>
      <gravity>1</gravity>
      <velocity_decay>
        <linear>0</linear>
        <angular>0</angular>
      </velocity_decay>
      <self_collide>0</self_collide>
      <sensor name='ffproximal_contact' type='contact'>
        <always_on>1</always_on>
        <update_rate>1000</update_rate>
        <contact>
          <collision>ffproximal_collision</collision>
          <topic>ffproximal_collision</topic>
        </contact>
      </sensor>
    </link>
    <joint name='FFJ3' type='revolute'>
      <child>ffproximal</child>
      <parent>ffknuckle</parent>
      <axis>
        <xyz>9.63268e-05 -1 5.55112e-17</xyz>
        <limit>
          <lower>0</lower>
          <upper>1.5708</upper>
          <effort>1000</effort>
          <velocity>10</velocity>
        </limit>
        <dynamics>
          <damping>1</damping>
          <friction>0</friction>
          <spring_reference>0</spring_reference>
          <spring_stiffness>0</spring_stiffness>
        </dynamics>
        <use_parent_model_frame>1</use_parent_model_frame>
      </axis>
      <physics>
        <provide_feedback>1</provide_feedback>
        <ode>
          <provide_feedback>1</provide_feedback>
          <implicit_spring_damper>1</implicit_spring_damper>
          <cfm_damping>1</cfm_damping>
          <limit>
            <cfm>0</cfm>
            <erp>0.2</erp>
          </limit>
        </ode>
      </physics>
    </joint>
    <link name='ffmiddle'>
      <pose>-0.386998 -0.0330373 1.29004 1.5707 -5.55112e-17 -1.5707</pose>
      <inertial>
        <pose>0 0 0.0125 0 -0 0</pose>
        <mass>0.012</mass>
        <inertia>
          <ixx>8e-07</ixx>
          <ixy>0</ixy>
          <ixz>0</ixz>
          <iyy>8e-07</iyy>
          <iyz>0</iyz>
          <izz>3e-07</izz>
        </inertia>
      </inertial>
      <collision name='ffmiddle_collision'>
        <pose>0 0 0.015 0 -0 1.5707</pose>
        <geometry>
          <cylinder>
            <length>0.028</length>
            <radius>0.008</radius>
          </cylinder>
        </geometry>
        <surface>
          <contact>
            <ode>
              <kp>100000</kp>
              <kd>100</kd>
              <max_vel>0.1</max_vel>
              <min_depth>0.0015</min_depth>
            </ode>
          </contact>
          <friction>
            <ode>
              <mu>1</mu>
              <mu2>1</mu2>
            </ode>
          </friction>
        </surface>
      </collision>
      <visual name='ffmiddle_visual'>
        <pose>0 0 0 0 -0 0</pose>
        <geometry>
          <mesh>
            <scale>0.001 0.001 0.001</scale>
            <uri>model://sr_description/hand/model/F2.dae</uri>
          </mesh>
        </geometry>
        <material>
          <script>
            <name>LightGrey</name>
            <uri>__default__</uri>
          </script>
        </material>
      </visual>
      <gravity>1</gravity>
      <velocity_decay>
        <linear>0</linear>
        <angular>0</angular>
      </velocity_decay>
      <self_collide>0</self_collide>
      <sensor name='ffmiddle_contact' type='contact'>
        <always_on>1</always_on>
        <update_rate>1000</update_rate>
        <contact>
          <collision>ffmiddle_collision</collision>
          <topic>ffmiddle_collision</topic>
        </contact>
      </sensor>
    </link>
    <joint name='FFJ2' type='revolute'>
      <child>ffmiddle</child>
      <parent>ffproximal</parent>
      <axis>
        <xyz>9.63268e-05 -1 5.55112e-17</xyz>
        <limit>
          <lower>0</lower>
          <upper>1.5708</upper>
          <effort>1000</effort>
          <velocity>10</velocity>
        </limit>
        <dynamics>
          <damping>1</damping>
          <friction>0</friction>
          <spring_reference>0</spring_reference>
          <spring_stiffness>0</spring_stiffness>
        </dynamics>
        <use_parent_model_frame>1</use_parent_model_frame>
      </axis>
      <physics>
        <provide_feedback>1</provide_feedback>
        <ode>
          <provide_feedback>1</provide_feedback>
          <implicit_spring_damper>1</implicit_spring_damper>
          <cfm_damping>1</cfm_damping>
          <limit>
            <cfm>0</cfm>
            <erp>0.2</erp>
          </limit>
        </ode>
      </physics>
    </joint>
    <link name='ffdistal'>
      <pose>-0.411998 -0.0330397 1.29004 1.5707 -5.55112e-17 -1.5707</pose>
      <inertial>
        <pose>0 0 0.0141818 0 -0 0</pose>
        <mass>0.011</mass>
        <inertia>
          <ixx>3.53636e-07</ixx>
          <ixy>0</ixy>
          <ixz>0</ixz>
          <iyy>3.53636e-07</iyy>
          <iyz>0</iyz>
          <izz>2e-07</izz>
        </inertia>
      </inertial>
      <collision name='ffdistal_collision'>
        <pose>0 0 0 0 -0 0</pose>
        <geometry>
          <mesh>
            <scale>0.001 0.001 0.001</scale>
            <uri>model://sr_description/hand/model/F1.dae</uri>
          </mesh>
        </geometry>
        <surface>
          <contact>
            <ode>
              <kp>100000</kp>
              <kd>100</kd>
              <max_vel>0.1</max_vel>
              <min_depth>0.0015</min_depth>
            </ode>
          </contact>
          <friction>
            <ode>
              <mu>1</mu>
              <mu2>1</mu2>
            </ode>
          </friction>
        </surface>
      </collision>
      <visual name='ffdistal_visual'>
        <pose>0 0 0 0 -0 0</pose>
        <geometry>
          <mesh>
            <scale>0.001 0.001 0.001</scale>
            <uri>model://sr_description/hand/model/F1.dae</uri>
          </mesh>
        </geometry>
        <material>
          <script>
            <name>LightGrey</name>
            <uri>__default__</uri>
          </script>
        </material>
      </visual>
      <gravity>1</gravity>
      <velocity_decay>
        <linear>0</linear>
        <angular>0</angular>
      </velocity_decay>
      <self_collide>0</self_collide>
      <sensor name='ffdistal_contact' type='contact'>
        <always_on>1</always_on>
        <update_rate>1000</update_rate>
        <contact>
          <collision>ffdistal_collision</collision>
          <topic>ffdistal_collision</topic>
        </contact>
      </sensor>
    </link>
    <joint name='FFJ1' type='revolute'>
      <child>ffdistal</child>
      <parent>ffmiddle</parent>
      <axis>
        <xyz>9.63268e-05 -1 5.55112e-17</xyz>
        <limit>
          <lower>0</lower>
          <upper>1.5708</upper>
          <effort>1000</effort>
          <velocity>10</velocity>
        </limit>
        <dynamics>
          <damping>3</damping>
          <friction>0</friction>
          <spring_reference>0</spring_reference>
          <spring_stiffness>0</spring_stiffness>
        </dynamics>
        <use_parent_model_frame>1</use_parent_model_frame>
      </axis>
      <physics>
        <provide_feedback>1</provide_feedback>
        <ode>
          <provide_feedback>1</provide_feedback>
          <implicit_spring_damper>1</implicit_spring_damper>
          <cfm_damping>1</cfm_damping>
          <limit>
            <cfm>0</cfm>
            <erp>0.2</erp>
          </limit>
        </ode>
      </physics>
    </joint>
    <link name='lfmetacarpal'>
      <pose>-0.267714 0.0329742 1.29003 1.5707 -5.55112e-17 -1.5707</pose>
      <inertial>
        <pose>0 0 0.04 0 -0 0</pose>
        <mass>0.075</mass>
        <inertia>
          <ixx>5e-06</ixx>
          <ixy>0</ixy>
          <ixz>0</ixz>
          <iyy>5e-06</iyy>
          <iyz>0</iyz>
          <izz>3e-06</izz>
        </inertia>
      </inertial>
      <collision name='lfmetacarpal_collision'>
        <pose>0 0 0.04 0 -0 0</pose>
        <geometry>
          <box>
            <size>0.019 0.019 0.05</size>
          </box>
        </geometry>
        <surface>
          <contact>
            <ode>
              <kp>100000</kp>
              <kd>100</kd>
              <max_vel>0.1</max_vel>
              <min_depth>0.0015</min_depth>
            </ode>
          </contact>
          <friction>
            <ode>
              <mu>1</mu>
              <mu2>1</mu2>
            </ode>
          </friction>
        </surface>
      </collision>
      <visual name='lfmetacarpal_visual'>
        <pose>0 0 0 0 -0 0</pose>
        <geometry>
          <mesh>
            <scale>0.001 0.001 0.001</scale>
            <uri>model://sr_description/hand/model/lfmetacarpal.dae</uri>
          </mesh>
        </geometry>
        <material>
          <script>
            <name>LightGrey</name>
            <uri>__default__</uri>
          </script>
        </material>
      </visual>
      <gravity>1</gravity>
      <velocity_decay>
        <linear>0</linear>
        <angular>0</angular>
      </velocity_decay>
      <self_collide>0</self_collide>
      <sensor name='lfmetacarpal_contact' type='contact'>
        <always_on>1</always_on>
        <update_rate>1000</update_rate>
        <contact>
          <collision>lfmetacarpal_collision</collision>
          <topic>lfmetacarpal_collision</topic>
        </contact>
      </sensor>
    </link>
    <joint name='LFJ5' type='revolute'>
      <child>lfmetacarpal</child>
      <parent>palm</parent>
      <axis>
        <xyz>-0.819097 -0.573655 7.89063e-05</xyz>
        <limit>
          <lower>0</lower>
          <upper>0.785398</upper>
          <effort>1000</effort>
          <velocity>10</velocity>
        </limit>
        <dynamics>
          <damping>1</damping>
          <friction>0</friction>
          <spring_reference>0</spring_reference>
          <spring_stiffness>0</spring_stiffness>
        </dynamics>
        <use_parent_model_frame>1</use_parent_model_frame>
      </axis>
      <physics>
        <provide_feedback>1</provide_feedback>
        <ode>
          <provide_feedback>1</provide_feedback>
          <implicit_spring_damper>1</implicit_spring_damper>
          <cfm_damping>1</cfm_damping>
          <limit>
            <cfm>0</cfm>
            <erp>0.2</erp>
          </limit>
        </ode>
      </physics>
    </joint>
    <link name='lfknuckle'>
      <pose>-0.333504 0.0329679 1.29003 1.5707 -5.55112e-17 -1.5707</pose>
      <inertial>
        <pose>0 0 0 0 -0 0</pose>
        <mass>0.008</mass>
        <inertia>
          <ixx>2e-07</ixx>
          <ixy>0</ixy>
          <ixz>0</ixz>
          <iyy>2e-07</iyy>
          <iyz>0</iyz>
          <izz>2e-07</izz>
        </inertia>
      </inertial>
      <collision name='lfknuckle_collision'>
        <pose>0 0 0 0 1.5707 0</pose>
        <geometry>
          <cylinder>
            <length>0.01</length>
            <radius>0.01</radius>
          </cylinder>
        </geometry>
        <surface>
          <contact>
            <ode>
              <kp>100000</kp>
              <kd>100</kd>
              <max_vel>0.1</max_vel>
              <min_depth>0.0015</min_depth>
            </ode>
          </contact>
          <friction>
            <ode>
              <mu>1</mu>
              <mu2>1</mu2>
            </ode>
          </friction>
        </surface>
      </collision>
      <visual name='lfknuckle_visual'>
        <pose>0 0 0.0005 0 -0 0</pose>
        <geometry>
          <mesh>
            <scale>0.001 0.001 0.001</scale>
            <uri>model://sr_description/hand/model/knuckle.dae</uri>
          </mesh>
        </geometry>
        <material>
          <script>
            <name>Gazebo/Grey</name>
            <uri>__default__</uri>
          </script>
        </material>
      </visual>
      <gravity>1</gravity>
      <velocity_decay>
        <linear>0</linear>
        <angular>0</angular>
      </velocity_decay>
      <self_collide>0</self_collide>
      <sensor name='lfknuckle_contact' type='contact'>
        <always_on>1</always_on>
        <update_rate>1000</update_rate>
        <contact>
          <collision>lfknuckle_collision</collision>
          <topic>lfknuckle_collision</topic>
        </contact>
      </sensor>
    </link>
    <joint name='LFJ4' type='revolute'>
      <child>lfknuckle</child>
      <parent>lfmetacarpal</parent>
      <axis>
        <xyz>9.63268e-05 9.27885e-09 1</xyz>
        <limit>
          <lower>-0.3491</lower>
          <upper>0.3491</upper>
          <effort>1000</effort>
          <velocity>10</velocity>
        </limit>
        <dynamics>
          <damping>1</damping>
          <friction>0</friction>
          <spring_reference>0</spring_reference>
          <spring_stiffness>0</spring_stiffness>
        </dynamics>
        <use_parent_model_frame>1</use_parent_model_frame>
      </axis>
      <physics>
        <provide_feedback>1</provide_feedback>
        <ode>
          <provide_feedback>1</provide_feedback>
          <implicit_spring_damper>1</implicit_spring_damper>
          <cfm_damping>1</cfm_damping>
          <limit>
            <cfm>0</cfm>
            <erp>0.2</erp>
          </limit>
        </ode>
      </physics>
    </joint>
    <link name='lfproximal'>
      <pose>-0.333504 0.0329679 1.29003 1.5707 -5.55112e-17 -1.5707</pose>
      <inertial>
        <pose>0 0 0.0225 0 -0 0</pose>
        <mass>0.014</mass>
        <inertia>
          <ixx>1e-06</ixx>
          <ixy>0</ixy>
          <ixz>0</ixz>
          <iyy>1e-06</iyy>
          <iyz>0</iyz>
          <izz>5e-07</izz>
        </inertia>
      </inertial>
      <collision name='lfproximal_collision'>
        <pose>0 0 0.025 0 -0 1.5707</pose>
        <geometry>
          <cylinder>
            <length>0.04</length>
            <radius>0.01</radius>
          </cylinder>
        </geometry>
        <surface>
          <contact>
            <ode>
              <kp>100000</kp>
              <kd>100</kd>
              <max_vel>0.1</max_vel>
              <min_depth>0.0015</min_depth>
            </ode>
          </contact>
          <friction>
            <ode>
              <mu>1</mu>
              <mu2>1</mu2>
            </ode>
          </friction>
        </surface>
      </collision>
      <visual name='lfproximal_visual'>
        <pose>0 0 0 0 -0 0</pose>
        <geometry>
          <mesh>
            <scale>0.001 0.001 0.001</scale>
            <uri>model://sr_description/hand/model/F3.dae</uri>
          </mesh>
        </geometry>
        <material>
          <script>
            <name>LightGrey</name>
            <uri>__default__</uri>
          </script>
        </material>
      </visual>
      <gravity>1</gravity>
      <velocity_decay>
        <linear>0</linear>
        <angular>0</angular>
      </velocity_decay>
      <self_collide>0</self_collide>
      <sensor name='lfproximal_contact' type='contact'>
        <always_on>1</always_on>
        <update_rate>1000</update_rate>
        <contact>
          <collision>lfproximal_collision</collision>
          <topic>lfproximal_collision</topic>
        </contact>
      </sensor>
    </link>
    <joint name='LFJ3' type='revolute'>
      <child>lfproximal</child>
      <parent>lfknuckle</parent>
      <axis>
        <xyz>9.63268e-05 -1 5.55112e-17</xyz>
        <limit>
          <lower>0</lower>
          <upper>1.5708</upper>
          <effort>1000</effort>
          <velocity>10</velocity>
        </limit>
        <dynamics>
          <damping>1</damping>
          <friction>0</friction>
          <spring_reference>0</spring_reference>
          <spring_stiffness>0</spring_stiffness>
        </dynamics>
        <use_parent_model_frame>1</use_parent_model_frame>
      </axis>
      <physics>
        <provide_feedback>1</provide_feedback>
        <ode>
          <provide_feedback>1</provide_feedback>
          <implicit_spring_damper>1</implicit_spring_damper>
          <cfm_damping>1</cfm_damping>
          <limit>
            <cfm>0</cfm>
            <erp>0.2</erp>
          </limit>
        </ode>
      </physics>
    </joint>
    <link name='lfmiddle'>
      <pose>-0.378504 0.0329635 1.29004 1.5707 -5.55112e-17 -1.5707</pose>
      <inertial>
        <pose>0 0 0.0125 0 -0 0</pose>
        <mass>0.012</mass>
        <inertia>
          <ixx>8e-07</ixx>
          <ixy>0</ixy>
          <ixz>0</ixz>
          <iyy>8e-07</iyy>
          <iyz>0</iyz>
          <izz>3e-07</izz>
        </inertia>
      </inertial>
      <collision name='lfmiddle_collision'>
        <pose>0 0 0.015 0 -0 0</pose>
        <geometry>
          <cylinder>
            <length>0.028</length>
            <radius>0.008</radius>
          </cylinder>
        </geometry>
        <surface>
          <contact>
            <ode>
              <kp>100000</kp>
              <kd>100</kd>
              <max_vel>0.1</max_vel>
              <min_depth>0.0015</min_depth>
            </ode>
          </contact>
          <friction>
            <ode>
              <mu>1</mu>
              <mu2>1</mu2>
            </ode>
          </friction>
        </surface>
      </collision>
      <visual name='lfmiddle_visual'>
        <pose>0 0 0 0 -0 0</pose>
        <geometry>
          <mesh>
            <scale>0.001 0.001 0.001</scale>
            <uri>model://sr_description/hand/model/F2.dae</uri>
          </mesh>
        </geometry>
        <material>
          <script>
            <name>LightGrey</name>
            <uri>__default__</uri>
          </script>
        </material>
      </visual>
      <gravity>1</gravity>
      <velocity_decay>
        <linear>0</linear>
        <angular>0</angular>
      </velocity_decay>
      <self_collide>0</self_collide>
      <sensor name='lfmiddle_contact' type='contact'>
        <always_on>1</always_on>
        <update_rate>1000</update_rate>
        <contact>
          <collision>lfmiddle_collision</collision>
          <topic>lfmiddle_collision</topic>
        </contact>
      </sensor>
    </link>
    <joint name='LFJ2' type='revolute'>
      <child>lfmiddle</child>
      <parent>lfproximal</parent>
      <axis>
        <xyz>9.63268e-05 -1 5.55112e-17</xyz>
        <limit>
          <lower>0</lower>
          <upper>1.5708</upper>
          <effort>1000</effort>
          <velocity>10</velocity>
        </limit>
        <dynamics>
          <damping>1</damping>
          <friction>0</friction>
          <spring_reference>0</spring_reference>
          <spring_stiffness>0</spring_stiffness>
        </dynamics>
        <use_parent_model_frame>1</use_parent_model_frame>
      </axis>
      <physics>
        <provide_feedback>1</provide_feedback>
        <ode>
          <provide_feedback>1</provide_feedback>
          <implicit_spring_damper>1</implicit_spring_damper>
          <cfm_damping>1</cfm_damping>
          <limit>
            <cfm>0</cfm>
            <erp>0.2</erp>
          </limit>
        </ode>
      </physics>
    </joint>
    <link name='lfdistal'>
      <pose>-0.403504 0.0329611 1.29004 1.5707 -5.55112e-17 -1.5707</pose>
      <inertial>
        <pose>0 0 0.0141818 0 -0 0</pose>
        <mass>0.011</mass>
        <inertia>
          <ixx>3.53636e-07</ixx>
          <ixy>0</ixy>
          <ixz>0</ixz>
          <iyy>3.53636e-07</iyy>
          <iyz>0</iyz>
          <izz>2e-07</izz>
        </inertia>
      </inertial>
      <collision name='lfdistal_collision'>
        <pose>0 0 0 0 -0 0</pose>
        <geometry>
          <mesh>
            <scale>0.001 0.001 0.001</scale>
            <uri>model://sr_description/hand/model/F1.dae</uri>
          </mesh>
        </geometry>
        <surface>
          <contact>
            <ode>
              <kp>100000</kp>
              <kd>100</kd>
              <max_vel>0.1</max_vel>
              <min_depth>0.0015</min_depth>
            </ode>
          </contact>
          <friction>
            <ode>
              <mu>1</mu>
              <mu2>1</mu2>
            </ode>
          </friction>
        </surface>
      </collision>
      <visual name='lfdistal_visual'>
        <pose>0 0 0 0 -0 0</pose>
        <geometry>
          <mesh>
            <scale>0.001 0.001 0.001</scale>
            <uri>model://sr_description/hand/model/F1.dae</uri>
          </mesh>
        </geometry>
        <material>
          <script>
            <name>LightGrey</name>
            <uri>__default__</uri>
          </script>
        </material>
      </visual>
      <gravity>1</gravity>
      <velocity_decay>
        <linear>0</linear>
        <angular>0</angular>
      </velocity_decay>
      <self_collide>0</self_collide>
      <sensor name='lfdistal_contact' type='contact'>
        <always_on>1</always_on>
        <update_rate>1000</update_rate>
        <contact>
          <collision>lfdistal_collision</collision>
          <topic>lfdistal_collision</topic>
        </contact>
      </sensor>
    </link>
    <joint name='LFJ1' type='revolute'>
      <child>lfdistal</child>
      <parent>lfmiddle</parent>
      <axis>
        <xyz>9.63268e-05 -1 5.55112e-17</xyz>
        <limit>
          <lower>0</lower>
          <upper>1.5708</upper>
          <effort>1000</effort>
          <velocity>10</velocity>
        </limit>
        <dynamics>
          <damping>3</damping>
          <friction>0</friction>
          <spring_reference>0</spring_reference>
          <spring_stiffness>0</spring_stiffness>
        </dynamics>
        <use_parent_model_frame>1</use_parent_model_frame>
      </axis>
      <physics>
        <provide_feedback>1</provide_feedback>
        <ode>
          <provide_feedback>1</provide_feedback>
          <implicit_spring_damper>1</implicit_spring_damper>
          <cfm_damping>1</cfm_damping>
          <limit>
            <cfm>0</cfm>
            <erp>0.2</erp>
          </limit>
        </ode>
      </physics>
    </joint>
    <link name='mfknuckle'>
      <pose>-0.346 -0.0110333 1.29003 1.5707 -5.55112e-17 -1.5707</pose>
      <inertial>
        <pose>0 0 0 0 -0 0</pose>
        <mass>0.008</mass>
        <inertia>
          <ixx>2e-07</ixx>
          <ixy>0</ixy>
          <ixz>0</ixz>
          <iyy>2e-07</iyy>
          <iyz>0</iyz>
          <izz>2e-07</izz>
        </inertia>
      </inertial>
      <collision name='mfknuckle_collision'>
        <pose>0 0 0 0 1.5707 0</pose>
        <geometry>
          <cylinder>
            <length>0.01</length>
            <radius>0.01</radius>
          </cylinder>
        </geometry>
        <surface>
          <contact>
            <ode>
              <kp>100000</kp>
              <kd>100</kd>
              <max_vel>0.1</max_vel>
              <min_depth>0.0015</min_depth>
            </ode>
          </contact>
          <friction>
            <ode>
              <mu>1</mu>
              <mu2>1</mu2>
            </ode>
          </friction>
        </surface>
      </collision>
      <visual name='mfknuckle_visual'>
        <pose>0 0 0.0005 0 -0 0</pose>
        <geometry>
          <mesh>
            <scale>0.001 0.001 0.001</scale>
            <uri>model://sr_description/hand/model/knuckle.dae</uri>
          </mesh>
        </geometry>
        <material>
          <script>
            <name>Gazebo/Grey</name>
            <uri>__default__</uri>
          </script>
        </material>
      </visual>
      <gravity>1</gravity>
      <velocity_decay>
        <linear>0</linear>
        <angular>0</angular>
      </velocity_decay>
      <self_collide>0</self_collide>
      <sensor name='mfknuckle_contact' type='contact'>
        <always_on>1</always_on>
        <update_rate>1000</update_rate>
        <contact>
          <collision>mfknuckle_collision</collision>
          <topic>mfknuckle_collision</topic>
        </contact>
      </sensor>
    </link>
    <joint name='MFJ4' type='revolute'>
      <child>mfknuckle</child>
      <parent>palm</parent>
      <axis>
        <xyz>-9.63268e-05 -9.27885e-09 -1</xyz>
        <limit>
          <lower>-0.3491</lower>
          <upper>0.3491</upper>
          <effort>1000</effort>
          <velocity>10</velocity>
        </limit>
        <dynamics>
          <damping>1</damping>
          <friction>0</friction>
          <spring_reference>0</spring_reference>
          <spring_stiffness>0</spring_stiffness>
        </dynamics>
        <use_parent_model_frame>1</use_parent_model_frame>
      </axis>
      <physics>
        <provide_feedback>1</provide_feedback>
        <ode>
          <provide_feedback>1</provide_feedback>
          <implicit_spring_damper>1</implicit_spring_damper>
          <cfm_damping>1</cfm_damping>
          <limit>
            <cfm>0</cfm>
            <erp>0.2</erp>
          </limit>
        </ode>
      </physics>
    </joint>
    <link name='mfproximal'>
      <pose>-0.346 -0.0110333 1.29003 1.5707 -5.55112e-17 -1.5707</pose>
      <inertial>
        <pose>0 0 0.0225 0 -0 0</pose>
        <mass>0.014</mass>
        <inertia>
          <ixx>1e-06</ixx>
          <ixy>0</ixy>
          <ixz>0</ixz>
          <iyy>1e-06</iyy>
          <iyz>0</iyz>
          <izz>5e-07</izz>
        </inertia>
      </inertial>
      <collision name='mfproximal_collision'>
        <pose>0 0 0.025 0 -0 1.5707</pose>
        <geometry>
          <cylinder>
            <length>0.04</length>
            <radius>0.01</radius>
          </cylinder>
        </geometry>
        <surface>
          <contact>
            <ode>
              <kp>100000</kp>
              <kd>100</kd>
              <max_vel>0.1</max_vel>
              <min_depth>0.0015</min_depth>
            </ode>
          </contact>
          <friction>
            <ode>
              <mu>1</mu>
              <mu2>1</mu2>
            </ode>
          </friction>
        </surface>
      </collision>
      <visual name='mfproximal_visual'>
        <pose>0 0 0 0 -0 0</pose>
        <geometry>
          <mesh>
            <scale>0.001 0.001 0.001</scale>
            <uri>model://sr_description/hand/model/F3.dae</uri>
          </mesh>
        </geometry>
        <material>
          <script>
            <name>LightGrey</name>
            <uri>__default__</uri>
          </script>
        </material>
      </visual>
      <gravity>1</gravity>
      <velocity_decay>
        <linear>0</linear>
        <angular>0</angular>
      </velocity_decay>
      <self_collide>0</self_collide>
      <sensor name='mfproximal_contact' type='contact'>
        <always_on>1</always_on>
        <update_rate>1000</update_rate>
        <contact>
          <collision>mfproximal_collision</collision>
          <topic>mfproximal_collision</topic>
        </contact>
      </sensor>
    </link>
    <joint name='MFJ3' type='revolute'>
      <child>mfproximal</child>
      <parent>mfknuckle</parent>
      <axis>
        <xyz>9.63268e-05 -1 5.55112e-17</xyz>
        <limit>
          <lower>0</lower>
          <upper>1.5708</upper>
          <effort>1000</effort>
          <velocity>10</velocity>
        </limit>
        <dynamics>
          <damping>1</damping>
          <friction>0</friction>
          <spring_reference>0</spring_reference>
          <spring_stiffness>0</spring_stiffness>
        </dynamics>
        <use_parent_model_frame>1</use_parent_model_frame>
      </axis>
      <physics>
        <provide_feedback>1</provide_feedback>
        <ode>
          <provide_feedback>1</provide_feedback>
          <implicit_spring_damper>1</implicit_spring_damper>
          <cfm_damping>1</cfm_damping>
          <limit>
            <cfm>0</cfm>
            <erp>0.2</erp>
          </limit>
        </ode>
      </physics>
    </joint>
    <link name='mfmiddle'>
      <pose>-0.391 -0.0110377 1.29004 1.5707 -5.55112e-17 -1.5707</pose>
      <inertial>
        <pose>0 0 0.0125 0 -0 0</pose>
        <mass>0.012</mass>
        <inertia>
          <ixx>8e-07</ixx>
          <ixy>0</ixy>
          <ixz>0</ixz>
          <iyy>8e-07</iyy>
          <iyz>0</iyz>
          <izz>3e-07</izz>
        </inertia>
      </inertial>
      <collision name='mfmiddle_collision'>
        <pose>0 0 0.015 0 -0 0</pose>
        <geometry>
          <cylinder>
            <length>0.028</length>
            <radius>0.008</radius>
          </cylinder>
        </geometry>
        <surface>
          <contact>
            <ode>
              <kp>100000</kp>
              <kd>100</kd>
              <max_vel>0.1</max_vel>
              <min_depth>0.0015</min_depth>
            </ode>
          </contact>
          <friction>
            <ode>
              <mu>1</mu>
              <mu2>1</mu2>
            </ode>
          </friction>
        </surface>
      </collision>
      <visual name='mfmiddle_visual'>
        <pose>0 0 0 0 -0 0</pose>
        <geometry>
          <mesh>
            <scale>0.001 0.001 0.001</scale>
            <uri>model://sr_description/hand/model/F2.dae</uri>
          </mesh>
        </geometry>
        <material>
          <script>
            <name>LightGrey</name>
            <uri>__default__</uri>
          </script>
        </material>
      </visual>
      <gravity>1</gravity>
      <velocity_decay>
        <linear>0</linear>
        <angular>0</angular>
      </velocity_decay>
      <self_collide>0</self_collide>
      <sensor name='mfmiddle_contact' type='contact'>
        <always_on>1</always_on>
        <update_rate>1000</update_rate>
        <contact>
          <collision>mfmiddle_collision</collision>
          <topic>mfmiddle_collision</topic>
        </contact>
      </sensor>
    </link>
    <joint name='MFJ2' type='revolute'>
      <child>mfmiddle</child>
      <parent>mfproximal</parent>
      <axis>
        <xyz>9.63268e-05 -1 5.55112e-17</xyz>
        <limit>
          <lower>0</lower>
          <upper>1.5708</upper>
          <effort>1000</effort>
          <velocity>10</velocity>
        </limit>
        <dynamics>
          <damping>1</damping>
          <friction>0</friction>
          <spring_reference>0</spring_reference>
          <spring_stiffness>0</spring_stiffness>
        </dynamics>
        <use_parent_model_frame>1</use_parent_model_frame>
      </axis>
      <physics>
        <provide_feedback>1</provide_feedback>
        <ode>
          <provide_feedback>1</provide_feedback>
          <implicit_spring_damper>1</implicit_spring_damper>
          <cfm_damping>1</cfm_damping>
          <limit>
            <cfm>0</cfm>
            <erp>0.2</erp>
          </limit>
        </ode>
      </physics>
    </joint>
    <link name='mfdistal'>
      <pose>-0.416 -0.0110401 1.29004 1.5707 -5.55112e-17 -1.5707</pose>
      <inertial>
        <pose>0 0 0.0141818 0 -0 0</pose>
        <mass>0.011</mass>
        <inertia>
          <ixx>3.53636e-07</ixx>
          <ixy>0</ixy>
          <ixz>0</ixz>
          <iyy>3.53636e-07</iyy>
          <iyz>0</iyz>
          <izz>2e-07</izz>
        </inertia>
      </inertial>
      <collision name='mfdistal_collision'>
        <pose>0 0 0 0 -0 0</pose>
        <geometry>
          <mesh>
            <scale>0.001 0.001 0.001</scale>
            <uri>model://sr_description/hand/model/F1.dae</uri>
          </mesh>
        </geometry>
        <surface>
          <contact>
            <ode>
              <kp>100000</kp>
              <kd>100</kd>
              <max_vel>0.1</max_vel>
              <min_depth>0.0015</min_depth>
            </ode>
          </contact>
          <friction>
            <ode>
              <mu>1</mu>
              <mu2>1</mu2>
            </ode>
          </friction>
        </surface>
      </collision>
      <visual name='mfdistal_visual'>
        <pose>0 0 0 0 -0 0</pose>
        <geometry>
          <mesh>
            <scale>0.001 0.001 0.001</scale>
            <uri>model://sr_description/hand/model/F1.dae</uri>
          </mesh>
        </geometry>
        <material>
          <script>
            <name>LightGrey</name>
            <uri>__default__</uri>
          </script>
        </material>
      </visual>
      <gravity>1</gravity>
      <velocity_decay>
        <linear>0</linear>
        <angular>0</angular>
      </velocity_decay>
      <self_collide>0</self_collide>
      <sensor name='mfdistal_contact' type='contact'>
        <always_on>1</always_on>
        <update_rate>1000</update_rate>
        <contact>
          <collision>mfdistal_collision</collision>
          <topic>mfdistal_collision</topic>
        </contact>
      </sensor>
    </link>
    <joint name='MFJ1' type='revolute'>
      <child>mfdistal</child>
      <parent>mfmiddle</parent>
      <axis>
        <xyz>9.63268e-05 -1 5.55112e-17</xyz>
        <limit>
          <lower>0</lower>
          <upper>1.5708</upper>
          <effort>1000</effort>
          <velocity>10</velocity>
        </limit>
        <dynamics>
          <damping>3</damping>
          <friction>0</friction>
          <spring_reference>0</spring_reference>
          <spring_stiffness>0</spring_stiffness>
        </dynamics>
        <use_parent_model_frame>1</use_parent_model_frame>
      </axis>
      <physics>
        <provide_feedback>1</provide_feedback>
        <ode>
          <provide_feedback>1</provide_feedback>
          <implicit_spring_damper>1</implicit_spring_damper>
          <cfm_damping>1</cfm_damping>
          <limit>
            <cfm>0</cfm>
            <erp>0.2</erp>
          </limit>
        </ode>
      </physics>
    </joint>
    <link name='rfknuckle'>
      <pose>-0.342002 0.0109671 1.29003 1.5707 -5.55112e-17 -1.5707</pose>
      <inertial>
        <pose>0 0 0 0 -0 0</pose>
        <mass>0.008</mass>
        <inertia>
          <ixx>2e-07</ixx>
          <ixy>0</ixy>
          <ixz>0</ixz>
          <iyy>2e-07</iyy>
          <iyz>0</iyz>
          <izz>2e-07</izz>
        </inertia>
      </inertial>
      <collision name='rfknuckle_collision'>
        <pose>0 0 0 0 1.5707 0</pose>
        <geometry>
          <cylinder>
            <length>0.01</length>
            <radius>0.01</radius>
          </cylinder>
        </geometry>
        <surface>
          <contact>
            <ode>
              <kp>100000</kp>
              <kd>100</kd>
              <max_vel>0.1</max_vel>
              <min_depth>0.0015</min_depth>
            </ode>
          </contact>
          <friction>
            <ode>
              <mu>1</mu>
              <mu2>1</mu2>
            </ode>
          </friction>
        </surface>
      </collision>
      <visual name='rfknuckle_visual'>
        <pose>0 0 0.0005 0 -0 0</pose>
        <geometry>
          <mesh>
            <scale>0.001 0.001 0.001</scale>
            <uri>model://sr_description/hand/model/knuckle.dae</uri>
          </mesh>
        </geometry>
        <material>
          <script>
            <name>Gazebo/Grey</name>
            <uri>__default__</uri>
          </script>
        </material>
      </visual>
      <gravity>1</gravity>
      <velocity_decay>
        <linear>0</linear>
        <angular>0</angular>
      </velocity_decay>
      <self_collide>0</self_collide>
      <sensor name='rfknuckle_contact' type='contact'>
        <always_on>1</always_on>
        <update_rate>1000</update_rate>
        <contact>
          <collision>rfknuckle_collision</collision>
          <topic>rfknuckle_collision</topic>
        </contact>
      </sensor>
    </link>
    <joint name='RFJ4' type='revolute'>
      <child>rfknuckle</child>
      <parent>palm</parent>
      <axis>
        <xyz>9.63268e-05 9.27885e-09 1</xyz>
        <limit>
          <lower>-0.3491</lower>
          <upper>0.3491</upper>
          <effort>1000</effort>
          <velocity>10</velocity>
        </limit>
        <dynamics>
          <damping>1</damping>
          <friction>0</friction>
          <spring_reference>0</spring_reference>
          <spring_stiffness>0</spring_stiffness>
        </dynamics>
        <use_parent_model_frame>1</use_parent_model_frame>
      </axis>
      <physics>
        <provide_feedback>1</provide_feedback>
        <ode>
          <provide_feedback>1</provide_feedback>
          <implicit_spring_damper>1</implicit_spring_damper>
          <cfm_damping>1</cfm_damping>
          <limit>
            <cfm>0</cfm>
            <erp>0.2</erp>
          </limit>
        </ode>
      </physics>
    </joint>
    <link name='rfproximal'>
      <pose>-0.342002 0.0109671 1.29003 1.5707 -5.55112e-17 -1.5707</pose>
      <inertial>
        <pose>0 0 0.0225 0 -0 0</pose>
        <mass>0.014</mass>
        <inertia>
          <ixx>1e-06</ixx>
          <ixy>0</ixy>
          <ixz>0</ixz>
          <iyy>1e-06</iyy>
          <iyz>0</iyz>
          <izz>5e-07</izz>
        </inertia>
      </inertial>
      <collision name='rfproximal_collision'>
        <pose>0 0 0.025 0 -0 1.5707</pose>
        <geometry>
          <cylinder>
            <length>0.04</length>
            <radius>0.01</radius>
          </cylinder>
        </geometry>
        <surface>
          <contact>
            <ode>
              <kp>100000</kp>
              <kd>100</kd>
              <max_vel>0.1</max_vel>
              <min_depth>0.0015</min_depth>
            </ode>
          </contact>
          <friction>
            <ode>
              <mu>1</mu>
              <mu2>1</mu2>
            </ode>
          </friction>
        </surface>
      </collision>
      <visual name='rfproximal_visual'>
        <pose>0 0 0 0 -0 0</pose>
        <geometry>
          <mesh>
            <scale>0.001 0.001 0.001</scale>
            <uri>model://sr_description/hand/model/F3.dae</uri>
          </mesh>
        </geometry>
        <material>
          <script>
            <name>LightGrey</name>
            <uri>__default__</uri>
          </script>
        </material>
      </visual>
      <gravity>1</gravity>
      <velocity_decay>
        <linear>0</linear>
        <angular>0</angular>
      </velocity_decay>
      <self_collide>0</self_collide>
      <sensor name='rfproximal_contact' type='contact'>
        <always_on>1</always_on>
        <update_rate>1000</update_rate>
        <contact>
          <collision>rfproximal_collision</collision>
          <topic>rfproximal_collision</topic>
        </contact>
      </sensor>
    </link>
    <joint name='RFJ3' type='revolute'>
      <child>rfproximal</child>
      <parent>rfknuckle</parent>
      <axis>
        <xyz>9.63268e-05 -1 5.55112e-17</xyz>
        <limit>
          <lower>0</lower>
          <upper>1.5708</upper>
          <effort>1000</effort>
          <velocity>10</velocity>
        </limit>
        <dynamics>
          <damping>1</damping>
          <friction>0</friction>
          <spring_reference>0</spring_reference>
          <spring_stiffness>0</spring_stiffness>
        </dynamics>
        <use_parent_model_frame>1</use_parent_model_frame>
      </axis>
      <physics>
        <provide_feedback>1</provide_feedback>
        <ode>
          <provide_feedback>1</provide_feedback>
          <implicit_spring_damper>1</implicit_spring_damper>
          <cfm_damping>1</cfm_damping>
          <limit>
            <cfm>0</cfm>
            <erp>0.2</erp>
          </limit>
        </ode>
      </physics>
    </joint>
    <link name='rfmiddle'>
      <pose>-0.387002 0.0109627 1.29004 1.5707 -5.55112e-17 -1.5707</pose>
      <inertial>
        <pose>0 0 0.0125 0 -0 0</pose>
        <mass>0.012</mass>
        <inertia>
          <ixx>8e-07</ixx>
          <ixy>0</ixy>
          <ixz>0</ixz>
          <iyy>8e-07</iyy>
          <iyz>0</iyz>
          <izz>3e-07</izz>
        </inertia>
      </inertial>
      <collision name='rfmiddle_collision'>
        <pose>0 0 0.015 0 -0 0</pose>
        <geometry>
          <cylinder>
            <length>0.028</length>
            <radius>0.008</radius>
          </cylinder>
        </geometry>
        <surface>
          <contact>
            <ode>
              <kp>100000</kp>
              <kd>100</kd>
              <max_vel>0.1</max_vel>
              <min_depth>0.0015</min_depth>
            </ode>
          </contact>
          <friction>
            <ode>
              <mu>1</mu>
              <mu2>1</mu2>
            </ode>
          </friction>
        </surface>
      </collision>
      <visual name='rfmiddle_visual'>
        <pose>0 0 0 0 -0 0</pose>
        <geometry>
          <mesh>
            <scale>0.001 0.001 0.001</scale>
            <uri>model://sr_description/hand/model/F2.dae</uri>
          </mesh>
        </geometry>
        <material>
          <script>
            <name>LightGrey</name>
            <uri>__default__</uri>
          </script>
        </material>
      </visual>
      <gravity>1</gravity>
      <velocity_decay>
        <linear>0</linear>
        <angular>0</angular>
      </velocity_decay>
      <self_collide>0</self_collide>
      <sensor name='rfmiddle_contact' type='contact'>
        <always_on>1</always_on>
        <update_rate>1000</update_rate>
        <contact>
          <collision>rfmiddle_collision</collision>
          <topic>rfmiddle_collision</topic>
        </contact>
      </sensor>
    </link>
    <joint name='RFJ2' type='revolute'>
      <child>rfmiddle</child>
      <parent>rfproximal</parent>
      <axis>
        <xyz>9.63268e-05 -1 5.55112e-17</xyz>
        <limit>
          <lower>0</lower>
          <upper>1.5708</upper>
          <effort>1000</effort>
          <velocity>10</velocity>
        </limit>
        <dynamics>
          <damping>1</damping>
          <friction>0</friction>
          <spring_reference>0</spring_reference>
          <spring_stiffness>0</spring_stiffness>
        </dynamics>
        <use_parent_model_frame>1</use_parent_model_frame>
      </axis>
      <physics>
        <provide_feedback>1</provide_feedback>
        <ode>
          <provide_feedback>1</provide_feedback>
          <implicit_spring_damper>1</implicit_spring_damper>
          <cfm_damping>1</cfm_damping>
          <limit>
            <cfm>0</cfm>
            <erp>0.2</erp>
          </limit>
        </ode>
      </physics>
    </joint>
    <link name='rfdistal'>
      <pose>-0.412002 0.0109603 1.29004 1.5707 -5.55112e-17 -1.5707</pose>
      <inertial>
        <pose>0 0 0.0141818 0 -0 0</pose>
        <mass>0.011</mass>
        <inertia>
          <ixx>3.53636e-07</ixx>
          <ixy>0</ixy>
          <ixz>0</ixz>
          <iyy>3.53636e-07</iyy>
          <iyz>0</iyz>
          <izz>2e-07</izz>
        </inertia>
      </inertial>
      <collision name='rfdistal_collision'>
        <pose>0 0 0 0 -0 0</pose>
        <geometry>
          <mesh>
            <scale>0.001 0.001 0.001</scale>
            <uri>model://sr_description/hand/model/F1.dae</uri>
          </mesh>
        </geometry>
        <surface>
          <contact>
            <ode>
              <kp>100000</kp>
              <kd>100</kd>
              <max_vel>0.1</max_vel>
              <min_depth>0.0015</min_depth>
            </ode>
          </contact>
          <friction>
            <ode>
              <mu>1</mu>
              <mu2>1</mu2>
            </ode>
          </friction>
        </surface>
      </collision>
      <visual name='rfdistal_visual'>
        <pose>0 0 0 0 -0 0</pose>
        <geometry>
          <mesh>
            <scale>0.001 0.001 0.001</scale>
            <uri>model://sr_description/hand/model/F1.dae</uri>
          </mesh>
        </geometry>
        <material>
          <script>
            <name>LightGrey</name>
            <uri>__default__</uri>
          </script>
        </material>
      </visual>
      <gravity>1</gravity>
      <velocity_decay>
        <linear>0</linear>
        <angular>0</angular>
      </velocity_decay>
      <self_collide>0</self_collide>
      <sensor name='rfdistal_contact' type='contact'>
        <always_on>1</always_on>
        <update_rate>1000</update_rate>
        <contact>
          <collision>rfdistal_collision</collision>
          <topic>rfdistal_collision</topic>
        </contact>
      </sensor>
    </link>
    <joint name='RFJ1' type='revolute'>
      <child>rfdistal</child>
      <parent>rfmiddle</parent>
      <axis>
        <xyz>9.63268e-05 -1 5.55112e-17</xyz>
        <limit>
          <lower>0</lower>
          <upper>1.5708</upper>
          <effort>1000</effort>
          <velocity>10</velocity>
        </limit>
        <dynamics>
          <damping>3</damping>
          <friction>0</friction>
          <spring_reference>0</spring_reference>
          <spring_stiffness>0</spring_stiffness>
        </dynamics>
        <use_parent_model_frame>1</use_parent_model_frame>
      </axis>
      <physics>
        <provide_feedback>1</provide_feedback>
        <ode>
          <provide_feedback>1</provide_feedback>
          <implicit_spring_damper>1</implicit_spring_damper>
          <cfm_damping>1</cfm_damping>
          <limit>
            <cfm>0</cfm>
            <erp>0.2</erp>
          </limit>
        </ode>
      </physics>
    </joint>
    <link name='thbase'>
      <pose>-0.275999 -0.0340266 1.28153 1.57073 6.81133e-05 -0.785302</pose>
      <inertial>
        <pose>0 0 0 0 -0 0</pose>
        <mass>0.01</mass>
        <inertia>
          <ixx>1e-06</ixx>
          <ixy>0</ixy>
          <ixz>0</ixz>
          <iyy>1e-06</iyy>
          <iyz>0</iyz>
          <izz>1e-06</izz>
        </inertia>
      </inertial>
      <collision name='thbase_collision'>
        <pose>0 0 0 0 -0 0</pose>
        <geometry>
          <sphere>
            <radius>0.0125</radius>
          </sphere>
        </geometry>
        <surface>
          <contact>
            <ode>
              <kp>100000</kp>
              <kd>100</kd>
              <max_vel>0.1</max_vel>
              <min_depth>0.0015</min_depth>
            </ode>
          </contact>
          <friction>
            <ode>
              <mu>1</mu>
              <mu2>1</mu2>
            </ode>
          </friction>
        </surface>
      </collision>
      <visual name='thbase_visual'>
        <pose>0 0 0 0 -0 0</pose>
        <geometry>
          <box>
            <size>0.001 0.001 0.001</size>
          </box>
        </geometry>
        <material>
          <script>
            <name>LightGrey</name>
            <uri>__default__</uri>
          </script>
        </material>
      </visual>
      <gravity>1</gravity>
      <velocity_decay>
        <linear>0</linear>
        <angular>0</angular>
      </velocity_decay>
      <self_collide>0</self_collide>
      <sensor name='thbase_contact' type='contact'>
        <always_on>1</always_on>
        <update_rate>1000</update_rate>
        <contact>
          <collision>thbase_collision</collision>
          <topic>thbase_collision</topic>
        </contact>
      </sensor>
    </link>
    <joint name='THJ5' type='revolute'>
      <child>thbase</child>
      <parent>palm</parent>
      <axis>
        <xyz>0.707039 0.707175 -6.81133e-05</xyz>
        <limit>
          <lower>-1.047</lower>
          <upper>1.047</upper>
          <effort>1000</effort>
          <velocity>10</velocity>
        </limit>
        <dynamics>
          <damping>1</damping>
          <friction>0</friction>
          <spring_reference>0</spring_reference>
          <spring_stiffness>0</spring_stiffness>
        </dynamics>
        <use_parent_model_frame>1</use_parent_model_frame>
      </axis>
      <physics>
        <provide_feedback>1</provide_feedback>
        <ode>
          <provide_feedback>1</provide_feedback>
          <implicit_spring_damper>1</implicit_spring_damper>
          <cfm_damping>1</cfm_damping>
          <limit>
            <cfm>0</cfm>
            <erp>0.2</erp>
          </limit>
        </ode>
      </physics>
    </joint>
    <link name='thproximal'>
      <pose>-0.275999 -0.0340266 1.28153 1.57073 6.81133e-05 -0.785302</pose>
      <inertial>
        <pose>0 0 0.019 0 -0 0</pose>
        <mass>0.016</mass>
        <inertia>
          <ixx>1e-06</ixx>
          <ixy>0</ixy>
          <ixz>0</ixz>
          <iyy>1e-06</iyy>
          <iyz>0</iyz>
          <izz>1e-06</izz>
        </inertia>
      </inertial>
      <collision name='thproximal_collision'>
        <pose>0 0 0.019 0 -0 1.5707</pose>
        <geometry>
          <cylinder>
            <length>0.04</length>
            <radius>0.01</radius>
          </cylinder>
        </geometry>
        <surface>
          <contact>
            <ode>
              <kp>100000</kp>
              <kd>100</kd>
              <max_vel>0.1</max_vel>
              <min_depth>0.0015</min_depth>
            </ode>
          </contact>
          <friction>
            <ode>
              <mu>1</mu>
              <mu2>1</mu2>
            </ode>
          </friction>
        </surface>
      </collision>
      <visual name='thproximal_visual'>
        <pose>0 0 0 0 -0 0</pose>
        <geometry>
          <mesh>
            <scale>0.001 0.001 0.001</scale>
            <uri>model://sr_description/hand/model/TH3_z.dae</uri>
          </mesh>
        </geometry>
        <material>
          <script>
            <name>LightGrey</name>
            <uri>__default__</uri>
          </script>
        </material>
      </visual>
      <gravity>1</gravity>
      <velocity_decay>
        <linear>0</linear>
        <angular>0</angular>
      </velocity_decay>
      <self_collide>0</self_collide>
      <sensor name='thproximal_contact' type='contact'>
        <always_on>1</always_on>
        <update_rate>1000</update_rate>
        <contact>
          <collision>thproximal_collision</collision>
          <topic>thproximal_collision</topic>
        </contact>
      </sensor>
    </link>
    <joint name='THJ4' type='revolute'>
      <child>thproximal</child>
      <parent>thbase</parent>
      <axis>
        <xyz>0.707175 -0.707039 -6.81133e-05</xyz>
        <limit>
          <lower>0</lower>
          <upper>1.309</upper>
          <effort>1000</effort>
          <velocity>10</velocity>
        </limit>
        <dynamics>
          <damping>1</damping>
          <friction>0</friction>
          <spring_reference>0</spring_reference>
          <spring_stiffness>0</spring_stiffness>
        </dynamics>
        <use_parent_model_frame>1</use_parent_model_frame>
      </axis>
      <physics>
        <provide_feedback>1</provide_feedback>
        <ode>
          <provide_feedback>1</provide_feedback>
          <implicit_spring_damper>1</implicit_spring_damper>
          <cfm_damping>1</cfm_damping>
          <limit>
            <cfm>0</cfm>
            <erp>0.2</erp>
          </limit>
        </ode>
      </physics>
    </joint>
    <link name='thhub'>
      <pose>-0.302866 -0.0608992 1.28153 1.57073 6.81133e-05 -0.785302</pose>
      <inertial>
        <pose>0 0 0 0 -0 0</pose>
        <mass>0.002</mass>
        <inertia>
          <ixx>1e-07</ixx>
          <ixy>0</ixy>
          <ixz>0</ixz>
          <iyy>1e-07</iyy>
          <iyz>0</iyz>
          <izz>1e-07</izz>
        </inertia>
      </inertial>
      <collision name='thhub_collision'>
        <pose>0 0 0 0 -0 0</pose>
        <geometry>
          <sphere>
            <radius>0.01</radius>
          </sphere>
        </geometry>
        <surface>
          <contact>
            <ode>
              <kp>100000</kp>
              <kd>100</kd>
              <max_vel>0.1</max_vel>
              <min_depth>0.0015</min_depth>
            </ode>
          </contact>
          <friction>
            <ode>
              <mu>1</mu>
              <mu2>1</mu2>
            </ode>
          </friction>
        </surface>
      </collision>
      <visual name='thhub_visual'>
        <pose>0 0 0 0 -0 0</pose>
        <geometry>
          <box>
            <size>0.001 0.001 0.001</size>
          </box>
        </geometry>
        <material>
          <script>
            <name>LightGrey</name>
            <uri>__default__</uri>
          </script>
        </material>
      </visual>
      <gravity>1</gravity>
      <velocity_decay>
        <linear>0</linear>
        <angular>0</angular>
      </velocity_decay>
      <self_collide>0</self_collide>
      <sensor name='thhub_contact' type='contact'>
        <always_on>1</always_on>
        <update_rate>1000</update_rate>
        <contact>
          <collision>thhub_collision</collision>
          <topic>thhub_collision</topic>
        </contact>
      </sensor>
    </link>
    <joint name='THJ3' type='revolute'>
      <child>thhub</child>
      <parent>thproximal</parent>
      <axis>
        <xyz>0.707175 -0.707039 -6.81133e-05</xyz>
        <limit>
          <lower>-0.2618</lower>
          <upper>0.2618</upper>
          <effort>1000</effort>
          <velocity>10</velocity>
        </limit>
        <dynamics>
          <damping>1</damping>
          <friction>0</friction>
          <spring_reference>0</spring_reference>
          <spring_stiffness>0</spring_stiffness>
        </dynamics>
        <use_parent_model_frame>1</use_parent_model_frame>
      </axis>
      <physics>
        <provide_feedback>1</provide_feedback>
        <ode>
          <provide_feedback>1</provide_feedback>
          <implicit_spring_damper>1</implicit_spring_damper>
          <cfm_damping>1</cfm_damping>
          <limit>
            <cfm>0</cfm>
            <erp>0.2</erp>
          </limit>
        </ode>
      </physics>
    </joint>
    <link name='thmiddle'>
      <pose>-0.302866 -0.0608992 1.28153 1.57073 6.81133e-05 -0.785302</pose>
      <inertial>
        <pose>0 0 0.016 0 -0 0</pose>
        <mass>0.016</mass>
        <inertia>
          <ixx>1e-06</ixx>
          <ixy>0</ixy>
          <ixz>0</ixz>
          <iyy>1e-06</iyy>
          <iyz>0</iyz>
          <izz>1e-06</izz>
        </inertia>
      </inertial>
      <collision name='thmiddle_collision'>
        <pose>0 0 0.017 0 -0 0</pose>
        <geometry>
          <cylinder>
            <length>0.03</length>
            <radius>0.01</radius>
          </cylinder>
        </geometry>
        <surface>
          <contact>
            <ode>
              <kp>100000</kp>
              <kd>100</kd>
              <max_vel>0.1</max_vel>
              <min_depth>0.0015</min_depth>
            </ode>
          </contact>
          <friction>
            <ode>
              <mu>1</mu>
              <mu2>1</mu2>
            </ode>
          </friction>
        </surface>
      </collision>
      <collision name='thmiddle_collision_thmiddle_1'>
        <pose>0 0 0.032 0 -0 0</pose>
        <geometry>
          <sphere>
            <radius>0.01</radius>
          </sphere>
        </geometry>
        <surface>
          <contact>
            <ode>
              <kp>100000</kp>
              <kd>100</kd>
              <max_vel>0.1</max_vel>
              <min_depth>0.0015</min_depth>
            </ode>
          </contact>
          <friction>
            <ode>
              <mu>1</mu>
              <mu2>1</mu2>
            </ode>
          </friction>
        </surface>
      </collision>
      <visual name='thmiddle_visual'>
        <pose>0 0 0 0 -0 0</pose>
        <geometry>
          <mesh>
            <scale>0.001 0.001 0.001</scale>
            <uri>model://sr_description/hand/model/TH2_z.dae</uri>
          </mesh>
        </geometry>
        <material>
          <script>
            <name>LightGrey</name>
            <uri>__default__</uri>
          </script>
        </material>
      </visual>
      <gravity>1</gravity>
      <velocity_decay>
        <linear>0</linear>
        <angular>0</angular>
      </velocity_decay>
      <self_collide>0</self_collide>
      <sensor name='thmiddle_contact' type='contact'>
        <always_on>1</always_on>
        <update_rate>1000</update_rate>
        <contact>
          <collision>thmiddle_collision</collision>
          <topic>thmiddle_collision</topic>
        </contact>
      </sensor>
    </link>
    <joint name='THJ2' type='revolute'>
      <child>thmiddle</child>
      <parent>thhub</parent>
      <axis>
        <xyz>-9.63268e-05 -9.27885e-09 -1</xyz>
        <limit>
          <lower>-0.6981</lower>
          <upper>0.6981</upper>
          <effort>1000</effort>
          <velocity>10</velocity>
        </limit>
        <dynamics>
          <damping>1</damping>
          <friction>0</friction>
          <spring_reference>0</spring_reference>
          <spring_stiffness>0</spring_stiffness>
        </dynamics>
        <use_parent_model_frame>1</use_parent_model_frame>
      </axis>
      <physics>
        <provide_feedback>1</provide_feedback>
        <ode>
          <provide_feedback>1</provide_feedback>
          <implicit_spring_damper>1</implicit_spring_damper>
          <cfm_damping>1</cfm_damping>
          <limit>
            <cfm>0</cfm>
            <erp>0.2</erp>
          </limit>
        </ode>
      </physics>
    </joint>
    <link name='thdistal'>
      <pose>-0.325491 -0.0835288 1.28153 -0.7854 1.5707 -3.1415</pose>
      <inertial>
        <pose>0 0 0.0145588 0 -0 0</pose>
        <mass>0.017</mass>
        <inertia>
          <ixx>1.17794e-06</ixx>
          <ixy>0</ixy>
          <ixz>0</ixz>
          <iyy>1.17794e-06</iyy>
          <iyz>0</iyz>
          <izz>1e-06</izz>
        </inertia>
      </inertial>
      <collision name='thdistal_collision'>
        <pose>0 0 0 0 -0 0</pose>
        <geometry>
          <mesh>
            <scale>0.001 0.001 0.001</scale>
            <uri>model://sr_description/hand/model/TH1_z.dae</uri>
          </mesh>
        </geometry>
        <surface>
          <contact>
            <ode>
              <kp>100000</kp>
              <kd>100</kd>
              <max_vel>0.1</max_vel>
              <min_depth>0.0015</min_depth>
            </ode>
          </contact>
          <friction>
            <ode>
              <mu>1</mu>
              <mu2>1</mu2>
            </ode>
          </friction>
        </surface>
      </collision>
      <visual name='thdistal_visual'>
        <pose>0 0 0 0 -0 0</pose>
        <geometry>
          <mesh>
            <scale>0.001 0.001 0.001</scale>
            <uri>model://sr_description/hand/model/TH1_z.dae</uri>
          </mesh>
        </geometry>
        <material>
          <script>
            <name>LightGrey</name>
            <uri>__default__</uri>
          </script>
        </material>
      </visual>
      <gravity>1</gravity>
      <velocity_decay>
        <linear>0</linear>
        <angular>0</angular>
      </velocity_decay>
      <self_collide>0</self_collide>
      <sensor name='thdistal_contact' type='contact'>
        <always_on>1</always_on>
        <update_rate>1000</update_rate>
        <contact>
          <collision>thdistal_collision</collision>
          <topic>thdistal_collision</topic>
        </contact>
      </sensor>
    </link>
    <joint name='THJ1' type='revolute'>
      <child>thdistal</child>
      <parent>thmiddle</parent>
      <axis>
        <xyz>-9.63269e-05 -9.13384e-09 -1</xyz>
        <limit>
          <lower>0</lower>
          <upper>1.571</upper>
          <effort>1000</effort>
          <velocity>10</velocity>
        </limit>
        <dynamics>
          <damping>3</damping>
          <friction>0</friction>
          <spring_reference>0</spring_reference>
          <spring_stiffness>0</spring_stiffness>
        </dynamics>
        <use_parent_model_frame>1</use_parent_model_frame>
      </axis>
      <physics>
        <provide_feedback>1</provide_feedback>
        <ode>
          <provide_feedback>1</provide_feedback>
          <implicit_spring_damper>1</implicit_spring_damper>
          <cfm_damping>1</cfm_damping>
          <limit>
            <cfm>0</cfm>
            <erp>0.2</erp>
          </limit>
        </ode>
      </physics>
    </joint>
    <static>0</static>
    <plugin name='HaptixControlPlugin' filename='libHaptixControlPlugin.so'>
      <base_joint>arm_base_joint</base_joint>
      <base_link>forearm</base_link>
      <base_pid_pos cmd_max='6000.0' cmd_min='-6000.0' d='200.0' i='0' p='1800.0'/>
      <base_pid_rot cmd_max='2000.0' cmd_min='-2000.0' d='100.0' i='0' p='1200.0'/>
      <base_link_to_spacenav_control_point>0 0 0 0 0 0</base_link_to_spacenav_control_point>
      <base_link_to_hydra_control_point>0 0 0 3.1416 1.5707 1.5707</base_link_to_hydra_control_point>
      <joint id='0'>WRJ2</joint>
      <joint id='1'>WRJ1</joint>
      <joint id='2'>FFJ4</joint>
      <joint id='3'>FFJ3</joint>
      <joint id='4'>FFJ2</joint>
      <joint id='5'>FFJ1</joint>
      <joint id='6'>MFJ4</joint>
      <joint id='7'>MFJ3</joint>
      <joint id='8'>MFJ2</joint>
      <joint id='9'>MFJ1</joint>
      <joint id='10'>RFJ4</joint>
      <joint id='11'>RFJ3</joint>
      <joint id='12'>RFJ2</joint>
      <joint id='13'>RFJ1</joint>
      <joint id='14'>LFJ5</joint>
      <joint id='15'>LFJ4</joint>
      <joint id='16'>LFJ3</joint>
      <joint id='17'>LFJ2</joint>
      <joint id='18'>LFJ1</joint>
      <joint id='19'>THJ5</joint>
      <joint id='20'>THJ4</joint>
      <joint id='21'>THJ3</joint>
      <joint id='22'>THJ2</joint>
      <joint id='23'>THJ1</joint>
      <pid cmd_max='500.0' cmd_min='-500.0' d='0' i='0' id='0' p='10.0'/>
      <pid cmd_max='500.0' cmd_min='-500.0' d='0' i='0' id='1' p='10.0'/>
      <pid cmd_max='100.0' cmd_min='-100.0' d='0' i='0' id='2' p='10.0'/>
      <pid cmd_max='100.0' cmd_min='-100.0' d='0' i='0' id='3' p='10.0'/>
      <pid cmd_max='100.0' cmd_min='-100.0' d='0' i='0' id='4' p='10.0'/>
      <pid cmd_max='100.0' cmd_min='-100.0' d='0' i='0' id='5' p='10.0'/>
      <pid cmd_max='100.0' cmd_min='-100.0' d='0' i='0' id='6' p='10.0'/>
      <pid cmd_max='100.0' cmd_min='-100.0' d='0' i='0' id='7' p='10.0'/>
      <pid cmd_max='100.0' cmd_min='-100.0' d='0' i='0' id='8' p='10.0'/>
      <pid cmd_max='100.0' cmd_min='-100.0' d='0' i='0' id='9' p='10.0'/>
      <pid cmd_max='100.0' cmd_min='-100.0' d='0' i='0' id='10' p='10.0'/>
      <pid cmd_max='100.0' cmd_min='-100.0' d='0' i='0' id='11' p='10.0'/>
      <pid cmd_max='100.0' cmd_min='-100.0' d='0' i='0' id='12' p='10.0'/>
      <pid cmd_max='100.0' cmd_min='-100.0' d='0' i='0' id='13' p='10.0'/>
      <pid cmd_max='100.0' cmd_min='-100.0' d='0' i='0' id='14' p='10.0'/>
      <pid cmd_max='100.0' cmd_min='-100.0' d='0' i='0' id='15' p='10.0'/>
      <pid cmd_max='100.0' cmd_min='-100.0' d='0' i='0' id='16' p='10.0'/>
      <pid cmd_max='100.0' cmd_min='-100.0' d='0' i='0' id='17' p='10.0'/>
      <pid cmd_max='100.0' cmd_min='-100.0' d='0' i='0' id='18' p='10.0'/>
      <pid cmd_max='100.0' cmd_min='-100.0' d='0' i='0' id='19' p='10.0'/>
      <pid cmd_max='100.0' cmd_min='-100.0' d='0' i='0' id='20' p='10.0'/>
      <pid cmd_max='100.0' cmd_min='-100.0' d='0' i='0' id='21' p='10.0'/>
      <pid cmd_max='100.0' cmd_min='-100.0' d='0' i='0' id='22' p='10.0'/>
      <pid cmd_max='100.0' cmd_min='-100.0' d='0' i='0' id='23' p='10.0'/>
      <motor id='0' name='motor_WRJ2'>
        <powered_motor_joint>WRJ2</powered_motor_joint>
        <motor_torque>0.0382</motor_torque>
        <gear_ratio>180.0</gear_ratio>
      </motor>
      <motor id='1' name='motor_WRJ1'>
        <powered_motor_joint>WRJ1</powered_motor_joint>
        <motor_torque>0.00955</motor_torque>
        <gear_ratio>180.0</gear_ratio>
      </motor>
      <motor id='2' name='motor_FFJ4'>
        <powered_motor_joint>FFJ4</powered_motor_joint>
        <motor_torque>3.82e-3</motor_torque>
        <gear_ratio>393.0</gear_ratio>
      </motor>
      <motor id='3' name='motor_FFJ3'>
        <powered_motor_joint>FFJ3</powered_motor_joint>
        <motor_torque>3.82e-3</motor_torque>
        <gear_ratio>393.0</gear_ratio>
        <gearbox>
          <joint>FFJ2</joint>
          <offset>0.174532925199</offset>
          <multiplier>0.8625</multiplier>
        </gearbox>
        <gearbox>
          <joint>FFJ1</joint>
          <offset>0.174532925199</offset>
          <multiplier>0.8375</multiplier>
        </gearbox>
      </motor>
      <motor id='4' name='motor_MFJ4'>
        <powered_motor_joint>MFJ4</powered_motor_joint>
        <motor_torque>3.82e-3</motor_torque>
        <gear_ratio>393.0</gear_ratio>
      </motor>
      <motor id='5' name='motor_MFJ3'>
        <powered_motor_joint>MFJ3</powered_motor_joint>
        <motor_torque>3.82e-3</motor_torque>
        <gear_ratio>393.0</gear_ratio>
        <gearbox>
          <joint>MFJ2</joint>
          <offset>0.174532925199</offset>
          <multiplier>0.8625</multiplier>
        </gearbox>
        <gearbox>
          <joint>MFJ1</joint>
          <offset>0.174532925199</offset>
          <multiplier>0.8375</multiplier>
        </gearbox>
      </motor>
      <motor id='6' name='motor_RFJ4'>
        <powered_motor_joint>RFJ4</powered_motor_joint>
        <motor_torque>3.82e-3</motor_torque>
        <gear_ratio>393.0</gear_ratio>
      </motor>
      <motor id='7' name='motor_RFJ3'>
        <powered_motor_joint>RFJ3</powered_motor_joint>
        <motor_torque>3.82e-3</motor_torque>
        <gear_ratio>393.0</gear_ratio>
        <gearbox>
          <joint>RFJ2</joint>
          <offset>0.174532925199</offset>
          <multiplier>0.8625</multiplier>
        </gearbox>
        <gearbox>
          <joint>RFJ1</joint>
          <offset>0.174532925199</offset>
          <multiplier>0.8375</multiplier>
        </gearbox>
      </motor>
      <motor id='8' name='motor_LFJ5'>
        <powered_motor_joint>LFJ5</powered_motor_joint>
        <motor_torque>3.82e-3</motor_torque>
        <gear_ratio>393.0</gear_ratio>
      </motor>
      <motor id='9' name='motor_LFJ4'>
        <powered_motor_joint>LFJ4</powered_motor_joint>
        <motor_torque>3.82e-3</motor_torque>
        <gear_ratio>393.0</gear_ratio>
      </motor>
      <motor id='10' name='motor_LFJ2'>
        <powered_motor_joint>LFJ3</powered_motor_joint>
        <motor_torque>3.82e-3</motor_torque>
        <gear_ratio>393.0</gear_ratio>
        <gearbox>
          <joint>LFJ2</joint>
          <offset>0.174532925199</offset>
          <multiplier>0.8625</multiplier>
        </gearbox>
        <gearbox>
          <joint>LFJ1</joint>
          <offset>0.174532925199</offset>
          <multiplier>0.8375</multiplier>
        </gearbox>
      </motor>
      <motor id='11' name='motor_THJ5'>
        <powered_motor_joint>THJ5</powered_motor_joint>
        <motor_torque>3.82e-3</motor_torque>
        <gear_ratio>393.0</gear_ratio>
      </motor>
      <motor id='12' name='motor_THJ4'>
        <powered_motor_joint>THJ4</powered_motor_joint>
        <motor_torque>3.82e-3</motor_torque>
        <gear_ratio>393.0</gear_ratio>
      </motor>
      <motor id='13' name='motor_THJ3'>
        <powered_motor_joint>THJ3</powered_motor_joint>
        <motor_torque>3.82e-3</motor_torque>
        <gear_ratio>393.0</gear_ratio>
        <gearbox>
          <joint>THJ2</joint>
          <offset>0.174532925199</offset>
          <multiplier>0.8625</multiplier>
        </gearbox>
        <gearbox>
          <joint>THJ1</joint>
          <offset>0.174532925199</offset>
          <multiplier>0.8375</multiplier>
        </gearbox>
      </motor>
      <contactSensor id='0'>palm_contact</contactSensor>
      <contactSensor id='1'>ffknuckle_contact</contactSensor>
      <contactSensor id='2'>ffproximal_contact</contactSensor>
      <contactSensor id='3'>ffmiddle_contact</contactSensor>
      <contactSensor id='4'>ffdistal_contact</contactSensor>
      <contactSensor id='5'>mfknuckle_contact</contactSensor>
      <contactSensor id='6'>mfproximal_contact</contactSensor>
      <contactSensor id='7'>mfmiddle_contact</contactSensor>
      <contactSensor id='8'>mfdistal_contact</contactSensor>
      <contactSensor id='9'>rfknuckle_contact</contactSensor>
      <contactSensor id='10'>rfproximal_contact</contactSensor>
      <contactSensor id='11'>rfmiddle_contact</contactSensor>
      <contactSensor id='12'>rfdistal_contact</contactSensor>
      <contactSensor id='13'>lfmetacarpal_contact</contactSensor>
      <contactSensor id='14'>lfknuckle_contact</contactSensor>
      <contactSensor id='15'>lfproximal_contact</contactSensor>
      <contactSensor id='16'>lfmiddle_contact</contactSensor>
      <contactSensor id='17'>lfdistal_contact</contactSensor>
      <contactSensor id='18'>thbase_contact</contactSensor>
      <contactSensor id='19'>thproximal_contact</contactSensor>
      <contactSensor id='20'>thhub_contact</contactSensor>
      <contactSensor id='21'>thmiddle_contact</contactSensor>
      <contactSensor id='22'>thdistal_contact</contactSensor>
      <grasp name='Cylindrical'>0 0 0 1.0 0 1.0 0 1.0 0 0 1.0 1.0 3.5 0.6</grasp>
      <grasp name='Spherical'>0 0 0 1.0 0 1.0 0 1.0 0 0 1.0 0.5 3.5 0.3</grasp>
      <grasp name='ThreeFingerPinch'>0 0 0 1.0 0 1.0 0 1.0 0 0 1.0 0.5 3.5 0.3</grasp>
      <grasp name='FinePinch(American)'>0 0 0 1.0 0 1.0 0 1.0 0 0 1.0 0.5 3.5 0.3</grasp>
      <grasp name='FinePinch(British)'>0 0 0 1.0 0 1.0 0 1.0 0 0 1.0 0.5 3.5 0.3</grasp>
      <grasp name='Palmar(Tray)'>0 0 0 1.0 0 1.0 0 1.0 0 0 1.0 0.5 3.5 0.3</grasp>
      <grasp name='Hook'>0 0 0 1.0 0 1.0 0 1.0 0 0 1.0 0.5 3.5 0.3</grasp>
    </plugin>
  </model>
</sdf>
